// This code defines an asyncHandler, a higher-order function designed to wrap asynchronous route handlers in an Express application. It ensures that errors in asynchronous code are caught and passed to the next() function, allowing for centralized error handling. Let me break down the code and concepts: 
 
 
 
const asyncHandler = (requestHandler) => {
    // Returns a new function that takes `req`, `res`, and `next` as parameters
    (req, res, next) => {
        // Executes the `requestHandler` (which is the original route handler),
        // wrapping it in a Promise. If it rejects (errors out), the error is caught and passed to `next`.
        Promise.resolve(requestHandler(req, res, next))
            .catch((err) => next(err));  // Catches any error and forwards it to the next middleware (error handler).
    }
}

export { asyncHandler };



// Explanation:
// 1. const asyncHandler = (requestHandler) => {}: Defines a higher-order function asyncHandler that takes a requestHandler (the route handler function) as its argument.
// 2. Inside, it returns a function that expects Express parameters (req, res, next).
// 3. Promise.resolve(requestHandler(req, res, next)): Ensures the requestHandler is executed and resolved as a promise, even if it's an asynchronous function (or returns a promise).
// 4 .  .catch((err) => next(err)): Catches any errors from the promise and forwards them to Express' error-handling middleware via next(err).

















// 2. try catch method


// const asyncHandler = () =>{}
// const asyncHandler = (fn) => ()=>{}
// const asyncHandler = (fn) => async()=>{}

//higher order function
// const asyncHandler = (fn) => async (req, res, next) => {
//     try {
//         // Await the execution of the passed function `fn`
//         await fn(req, res, next);
//     } catch (err) {
//         // If an error is caught, send a JSON response with error details
//         res.status(err.code || 500).json({
//             success: false,           // Indicates failure
//             message: err.message,     // Error message from the caught error
//         });
//     }
// };



// Breakdown:
// 1. const asyncHandler = (fn) => async (req, res, next) => {}: This version takes the handler function fn and returns an async function that handles requests.
// 2. try { await fn(req, res, next); }: Executes the passed function fn, using await to handle asynchronous operations.
// 3. catch (err): If any error occurs, it's caught in the catch block.
// 4. res.status(err.code || 500).json({ ... }): Instead of forwarding the error to the next middleware, this approach sends a JSON response directly, with the status code and message.

// Comparison:

// 1. First method (Promise.resolve): This method ensures that errors in asynchronous functions are caught and passed to next(err), enabling centralized error handling in Express (where you may define custom error-handling middleware).

// 2. Second method (try-catch): This version directly handles the error in the catch block and responds with a JSON error message. It may be useful when you want to send an immediate response from within the handler, rather than relying on centralized middleware.

// Both methods effectively handle errors in asynchronous route handlers, but the first one delegates the error handling to centralized middleware, while the second responds directly in the route handler.











